Workbook

Sheet DATA
B2: MILES | C2: BIL | D2: BOI | E2: GRR | F2: GJJ | G2: GFV | H2: IDF | I2: MIS | J2: NoCo | K2: OGD | L2: RMV | O2: TIME | P2: BIL | Q2: BOI | R2: GRR | S2: GJJ | T2: GFV | U2: IDF | V2: MIS | W2: NoCo | X2: OGD | Y2: RMV
B3: Billings | C3: X | D3: 599 | E3: 420 | F3: 662 | G3: 218 | H3: 340 | I3: 345 | J3: 508 | K3: 515 | L3: 621 | O3: Billings | P3: 0 | Q3: 0.40625 | R3: 0.29861111 | S3: 0.4375 | T3: 0.15625 | U3: 0.23611111 | V3: 0.22569444 | W3: 0.32291667 | X3: 0.33680556 | Y3: 0.40277778
B4: Boise | C4: 620 | D4: X | E4: 482 | F4: 628 | G4: 585 | H4: 264 | I4: 359 | J4: 778 | K4: 312 | L4: 891 | O4: Boise | P4: 0.39930556 | Q4: 0 | R4: 0.39583333 | S4: 0.39236111 | T4: 0.38194444 | U4: 0.17708333 | V4: 0.29861111 | W4: 0.48611111 | X4: 0.19444444 | Y4: 0.55902778
B5: Glacier | C5: 420 | D5: 482 | E5: X | F5: 919 | G5: 225 | H5: 426 | I5: 126 | J5: 948 | K5: 603 | L5: 1061 | O5: Glacier | P5: 0.29166667 | Q5: 0.39583333 | R5: 0 | S5: 0.58333333 | T5: 0.15625 | U5: 0.28125 | V5: 0.097222222 | W5: 0.59375 | X5: 0.38194444 | Y5: 0.67361111
B6: Grand Junction | C6: 663 | D6: 627 | E6: 920 | F6: X | G6: 855 | H6: 495 | I6: 807 | J6: 298 | K6: 319 | L6: 311 | O6: Grand Junction | P6: 0.42361111 | Q6: 0.39236111 | R6: 0.58680556 | S6: 0 | T6: 0.52777778 | U6: 0.30902778 | V6: 0.48958333 | W6: 0.20833333 | X6: 0.20833333 | Y6: 0.21527778
B7: Great Falls | C7: 218 | D7: 584 | E7: 225 | F7: 855 | G7: X | H7: 362 | I7: 169 | J7: 726 | K7: 539 | L7: 839 | O7: Great Falls | P7: 0.15277778 | Q7: 0.37847222 | R7: 0.15625 | S7: 0.53472222 | T7: 0 | U7: 0.23263889 | V7: 0.11805556 | W7: 0.45833333 | X7: 0.33333333 | Y7: 0.53125
B8: Idaho Falls | C8: 338 | D8: 264 | E8: 427 | F8: 496 | G8: 362 | H8: X | I8: 314 | J8: 548 | K8: 180 | L8: 661 | O8: Idaho Falls | P8: 0.23611111 | Q8: 0.18055556 | R8: 0.28125 | S8: 0.3125 | T8: 0.23958333 | U8: 0 | V8: 0.19791667 | W8: 0.36805556 | X8: 0.11111111 | Y8: 0.44097222
B9: Missoula | C9: 345 | D9: 359 | E9: 125 | F9: 806 | G9: 169 | H9: 313 | I9: X | J9: 852 | K9: 490 | L9: 965 | O9: Missoula | P9: 0.22083333 | Q9: 0.30555556 | R9: 0.097222222 | S9: 0.50347222 | T9: 0.11805556 | U9: 0.20138889 | V9: 0 | W9: 0.52430556 | X9: 0.30208333 | Y9: 0.59722222
B10: NoCo | C10: 507 | D10: 775 | E10: 947 | F10: 298 | G10: 725 | H10: 546 | I10: 851 | J10: X | K10: 467 | L10: 126 | O10: NoCo | P10: 0.31944444 | Q10: 0.48263889 | R10: 0.61805556 | S10: 0.21180556 | T10: 0.46527778 | U10: 0.36805556 | V10: 0.52430556 | W10: 0 | X10: 0.30208333 | Y10: 0.086805556
B11: Ogden | C11: 516 | D11: 311 | E11: 604 | F11: 319 | G11: 539 | H11: 179 | I11: 491 | J11: 469 | K11: X | L11: 583 | O11: Ogden | P11: 0.34375 | Q11: 0.19791667 | R11: 0.39236111 | S11: 0.20833333 | T11: 0.34027778 | U11: 0.11111111 | V11: 0.30555556 | W11: 0.30555556 | X11: 0 | Y11: 0.38541667
B12: Rocky Mountain | C12: 621 | D12: 889 | E12: 1061 | F12: 310 | G12: 838 | H12: 659 | I12: 965 | J12: 125 | K12: 580 | L12: X | O12: Rocky Mountain | P12: 0.38541667 | Q12: 0.55208333 | R12: 0.68055556 | S12: 0.21875 | T12: 0.52777778 | U12: 0.44097222 | V12: 0.58680556 | W12: 0.086805556 | X12: 0.36805556 | Y12: 0
B15: HOME GAMES | C15: BIL | D15: BOI | E15: GRR | F15: GJJ | G15: GFV | H15: IDF | I15: MIS | J15: NoCo | K15: OGD | L15: RMV | M15: TOTAL | O15: TIME | P15: BIL | Q15: GRR | R15: GFV | S15: IDF | T15: MIS | U15: BOI | V15: GJJ | W15: NoCo | X15: OGD | Y15: RMV
B16: Billings | C16: x | D16: =COUNTIFS(Events!$F$2:$F$481,$B16,Events!$G$2:$G$481,D$15) -> 0 | E16: =COUNTIFS(Events!$F$2:$F$481,$B16,Events!$G$2:$G$481,E$15) -> 15 | F16: =COUNTIFS(Events!$F$2:$F$481,$B16,Events!$G$2:$G$481,F$15) -> 0 | G16: =COUNTIFS(Events!$F$2:$F$481,$B16,Events!$G$2:$G$481,G$15) -> 9 | H16: =COUNTIFS(Events!$F$2:$F$481,$B16,Events!$G$2:$G$481,H$15) -> 6 | I16: =COUNTIFS(Events!$F$2:$F$481,$B16,Events!$G$2:$G$481,I$15) -> 9 | J16: =COUNTIFS(Events!$F$2:$F$481,$B16,Events!$G$2:$G$481,J$15) -> 9 | K16: =COUNTIFS(Events!$F$2:$F$481,$B16,Events!$G$2:$G$481,K$15) -> 0 | L16: =COUNTIFS(Events!$F$2:$F$481,$B16,Events!$G$2:$G$481,L$15) -> 0 | M16: =SUM(C16:L16) -> 48 | O16: Billings | P16: 0 | Q16: 7.17 | R16: 3.75 | S16: 5.67 | T16: 5.42 | U16: 9.75 | V16: 10.5 | W16: 7.75 | X16: 8.08 | Y16: 9.67
B17: Boise | C17: =COUNTIFS(Events!$F$2:$F$481,$B17,Events!$G$2:$G$481,C$15) -> 6 | D17: x | E17: =COUNTIFS(Events!$F$2:$F$481,$B17,Events!$G$2:$G$481,E$15) -> 6 | F17: =COUNTIFS(Events!$F$2:$F$481,$B17,Events!$G$2:$G$481,F$15) -> 6 | G17: =COUNTIFS(Events!$F$2:$F$481,$B17,Events!$G$2:$G$481,G$15) -> 9 | H17: =COUNTIFS(Events!$F$2:$F$481,$B17,Events!$G$2:$G$481,H$15) -> 6 | I17: =COUNTIFS(Events!$F$2:$F$481,$B17,Events!$G$2:$G$481,I$15) -> 3 | J17: =COUNTIFS(Events!$F$2:$F$481,$B17,Events!$G$2:$G$481,J$15) -> 0 | K17: =COUNTIFS(Events!$F$2:$F$481,$B17,Events!$G$2:$G$481,K$15) -> 9 | L17: =COUNTIFS(Events!$F$2:$F$481,$B17,Events!$G$2:$G$481,L$15) -> 3 | M17: =SUM(C17:L17) -> 48 | O17: Glacier | P17: 7 | Q17: 0 | R17: 3.75 | S17: 6.75 | T17: 2.33 | U17: 9.5 | V17: 14 | W17: 14.25 | X17: 9.17 | Y17: 16.17
B18: Glacier | C18: =COUNTIFS(Events!$F$2:$F$481,$B18,Events!$G$2:$G$481,C$15) -> 6 | D18: =COUNTIFS(Events!$F$2:$F$481,$B18,Events!$G$2:$G$481,D$15) -> 3 | E18: x | F18: =COUNTIFS(Events!$F$2:$F$481,$B18,Events!$G$2:$G$481,F$15) -> 0 | G18: =COUNTIFS(Events!$F$2:$F$481,$B18,Events!$G$2:$G$481,G$15) -> 9 | H18: =COUNTIFS(Events!$F$2:$F$481,$B18,Events!$G$2:$G$481,H$15) -> 9 | I18: =COUNTIFS(Events!$F$2:$F$481,$B18,Events!$G$2:$G$481,I$15) -> 15 | J18: =COUNTIFS(Events!$F$2:$F$481,$B18,Events!$G$2:$G$481,J$15) -> 0 | K18: =COUNTIFS(Events!$F$2:$F$481,$B18,Events!$G$2:$G$481,K$15) -> 3 | L18: =COUNTIFS(Events!$F$2:$F$481,$B18,Events!$G$2:$G$481,L$15) -> 3 | M18: =SUM(C18:L18) -> 48 | O18: Great Falls | P18: 3.67 | Q18: 3.75 | R18: 0 | S18: 5.58 | T18: 2.83 | U18: 9.08 | V18: 12.83 | W18: 11 | X18: 8 | Y18: 12.75
B19: Grand Junction | C19: =COUNTIFS(Events!$F$2:$F$481,$B19,Events!$G$2:$G$481,C$15) -> 0 | D19: =COUNTIFS(Events!$F$2:$F$481,$B19,Events!$G$2:$G$481,D$15) -> 9 | E19: =COUNTIFS(Events!$F$2:$F$481,$B19,Events!$G$2:$G$481,E$15) -> 0 | F19: x | G19: =COUNTIFS(Events!$F$2:$F$481,$B19,Events!$G$2:$G$481,G$15) -> 0 | H19: =COUNTIFS(Events!$F$2:$F$481,$B19,Events!$G$2:$G$481,H$15) -> 3 | I19: =COUNTIFS(Events!$F$2:$F$481,$B19,Events!$G$2:$G$481,I$15) -> 0 | J19: =COUNTIFS(Events!$F$2:$F$481,$B19,Events!$G$2:$G$481,J$15) -> 18 | K19: =COUNTIFS(Events!$F$2:$F$481,$B19,Events!$G$2:$G$481,K$15) -> 3 | L19: =COUNTIFS(Events!$F$2:$F$481,$B19,Events!$G$2:$G$481,L$15) -> 15 | M19: =SUM(C19:L19) -> 48 | O19: Idaho Falls | P19: 5.67 | Q19: 6.75 | R19: 5.75 | S19: 0 | T19: 4.75 | U19: 4.33 | V19: 7.5 | W19: 8.83 | X19: 2.67 | Y19: 10.58
B20: Great Falls | C20: =COUNTIFS(Events!$F$2:$F$481,$B20,Events!$G$2:$G$481,C$15) -> 12 | D20: =COUNTIFS(Events!$F$2:$F$481,$B20,Events!$G$2:$G$481,D$15) -> 9 | E20: =COUNTIFS(Events!$F$2:$F$481,$B20,Events!$G$2:$G$481,E$15) -> 9 | F20: =COUNTIFS(Events!$F$2:$F$481,$B20,Events!$G$2:$G$481,F$15) -> 0 | G20: x | H20: =COUNTIFS(Events!$F$2:$F$481,$B20,Events!$G$2:$G$481,H$15) -> 3 | I20: =COUNTIFS(Events!$F$2:$F$481,$B20,Events!$G$2:$G$481,I$15) -> 15 | J20: =COUNTIFS(Events!$F$2:$F$481,$B20,Events!$G$2:$G$481,J$15) -> 0 | K20: =COUNTIFS(Events!$F$2:$F$481,$B20,Events!$G$2:$G$481,K$15) -> 0 | L20: =COUNTIFS(Events!$F$2:$F$481,$B20,Events!$G$2:$G$481,L$15) -> 0 | M20: =SUM(C20:L20) -> 48 | O20: Missoula | P20: 5.3 | Q20: 2.33 | R20: 2.83 | S20: 4.83 | T20: 0 | U20: 7.33 | V20: 12.08 | W20: 12.58 | X20: 7.25 | Y20: 14.33
B21: Idaho Falls | C21: =COUNTIFS(Events!$F$2:$F$481,$B21,Events!$G$2:$G$481,C$15) -> 0 | D21: =COUNTIFS(Events!$F$2:$F$481,$B21,Events!$G$2:$G$481,D$15) -> 6 | E21: =COUNTIFS(Events!$F$2:$F$481,$B21,Events!$G$2:$G$481,E$15) -> 9 | F21: =COUNTIFS(Events!$F$2:$F$481,$B21,Events!$G$2:$G$481,F$15) -> 12 | G21: =COUNTIFS(Events!$F$2:$F$481,$B21,Events!$G$2:$G$481,G$15) -> 6 | H21: x | I21: =COUNTIFS(Events!$F$2:$F$481,$B21,Events!$G$2:$G$481,I$15) -> 6 | J21: =COUNTIFS(Events!$F$2:$F$481,$B21,Events!$G$2:$G$481,J$15) -> 0 | K21: =COUNTIFS(Events!$F$2:$F$481,$B21,Events!$G$2:$G$481,K$15) -> 6 | L21: =COUNTIFS(Events!$F$2:$F$481,$B21,Events!$G$2:$G$481,L$15) -> 3 | M21: =SUM(C21:L21) -> 48 | O21: Boise | P21: 9.58 | Q21: 9.5 | R21: 9.17 | S21: 4.25 | T21: 7.17 | U21: 0 | V21: 9.42 | W21: 11.67 | X21: 4.67 | Y21: 13.42
B22: Missoula | C22: =COUNTIFS(Events!$F$2:$F$481,$B22,Events!$G$2:$G$481,C$15) -> 9 | D22: =COUNTIFS(Events!$F$2:$F$481,$B22,Events!$G$2:$G$481,D$15) -> 6 | E22: =COUNTIFS(Events!$F$2:$F$481,$B22,Events!$G$2:$G$481,E$15) -> 9 | F22: =COUNTIFS(Events!$F$2:$F$481,$B22,Events!$G$2:$G$481,F$15) -> 0 | G22: =COUNTIFS(Events!$F$2:$F$481,$B22,Events!$G$2:$G$481,G$15) -> 9 | H22: =COUNTIFS(Events!$F$2:$F$481,$B22,Events!$G$2:$G$481,H$15) -> 3 | I22: x | J22: =COUNTIFS(Events!$F$2:$F$481,$B22,Events!$G$2:$G$481,J$15) -> 0 | K22: =COUNTIFS(Events!$F$2:$F$481,$B22,Events!$G$2:$G$481,K$15) -> 9 | L22: =COUNTIFS(Events!$F$2:$F$481,$B22,Events!$G$2:$G$481,L$15) -> 3 | M22: =SUM(C22:L22) -> 48 | O22: Grand Junction | P22: 10.17 | Q22: 14.08 | R22: 12.67 | S22: 7.42 | T22: 11.75 | U22: 9.42 | V22: 0 | W22: 5 | X22: 5 | Y22: 5.17
B23: NoCo | C23: =COUNTIFS(Events!$F$2:$F$481,$B23,Events!$G$2:$G$481,C$15) -> 6 | D23: =COUNTIFS(Events!$F$2:$F$481,$B23,Events!$G$2:$G$481,D$15) -> 3 | E23: =COUNTIFS(Events!$F$2:$F$481,$B23,Events!$G$2:$G$481,E$15) -> 0 | F23: =COUNTIFS(Events!$F$2:$F$481,$B23,Events!$G$2:$G$481,F$15) -> 12 | G23: =COUNTIFS(Events!$F$2:$F$481,$B23,Events!$G$2:$G$481,G$15) -> 6 | H23: =COUNTIFS(Events!$F$2:$F$481,$B23,Events!$G$2:$G$481,H$15) -> 6 | I23: =COUNTIFS(Events!$F$2:$F$481,$B23,Events!$G$2:$G$481,I$15) -> 0 | J23: x | K23: =COUNTIFS(Events!$F$2:$F$481,$B23,Events!$G$2:$G$481,K$15) -> 3 | L23: =COUNTIFS(Events!$F$2:$F$481,$B23,Events!$G$2:$G$481,L$15) -> 12 | M23: =SUM(C23:L23) -> 48 | O23: NoCo | P23: 7.67 | Q23: 14.83 | R23: 11.17 | S23: 8.83 | T23: 12.58 | U23: 11.58 | V23: 5.08 | W23: 0 | X23: 7.25 | Y23: 2.08
B24: Ogden | C24: =COUNTIFS(Events!$F$2:$F$481,$B24,Events!$G$2:$G$481,C$15) -> 6 | D24: =COUNTIFS(Events!$F$2:$F$481,$B24,Events!$G$2:$G$481,D$15) -> 9 | E24: =COUNTIFS(Events!$F$2:$F$481,$B24,Events!$G$2:$G$481,E$15) -> 0 | F24: =COUNTIFS(Events!$F$2:$F$481,$B24,Events!$G$2:$G$481,F$15) -> 6 | G24: =COUNTIFS(Events!$F$2:$F$481,$B24,Events!$G$2:$G$481,G$15) -> 0 | H24: =COUNTIFS(Events!$F$2:$F$481,$B24,Events!$G$2:$G$481,H$15) -> 12 | I24: =COUNTIFS(Events!$F$2:$F$481,$B24,Events!$G$2:$G$481,I$15) -> 0 | J24: =COUNTIFS(Events!$F$2:$F$481,$B24,Events!$G$2:$G$481,J$15) -> 6 | K24: x | L24: =COUNTIFS(Events!$F$2:$F$481,$B24,Events!$G$2:$G$481,L$15) -> 9 | M24: =SUM(C24:L24) -> 48 | O24: Ogden | P24: 8.25 | Q24: 9.42 | R24: 8.17 | S24: 2.67 | T24: 7.33 | U24: 4.75 | V24: 5 | W24: 7.33 | X24: 0 | Y24: 9.25
B25: Rocky Mountain | C25: =COUNTIFS(Events!$F$2:$F$481,$B25,Events!$G$2:$G$481,C$15) -> 3 | D25: =COUNTIFS(Events!$F$2:$F$481,$B25,Events!$G$2:$G$481,D$15) -> 3 | E25: =COUNTIFS(Events!$F$2:$F$481,$B25,Events!$G$2:$G$481,E$15) -> 0 | F25: =COUNTIFS(Events!$F$2:$F$481,$B25,Events!$G$2:$G$481,F$15) -> 12 | G25: =COUNTIFS(Events!$F$2:$F$481,$B25,Events!$G$2:$G$481,G$15) -> 0 | H25: =COUNTIFS(Events!$F$2:$F$481,$B25,Events!$G$2:$G$481,H$15) -> 0 | I25: =COUNTIFS(Events!$F$2:$F$481,$B25,Events!$G$2:$G$481,I$15) -> 0 | J25: =COUNTIFS(Events!$F$2:$F$481,$B25,Events!$G$2:$G$481,J$15) -> 15 | K25: =COUNTIFS(Events!$F$2:$F$481,$B25,Events!$G$2:$G$481,K$15) -> 15 | L25: x | M25: =SUM(C25:L25) -> 48 | O25: Rocky Mountain | P25: 9.25 | Q25: 16.33 | R25: 12.67 | S25: 10.58 | T25: 14.08 | U25: 13.25 | V25: 5.25 | W25: 2.08 | X25: 8.83 | Y25: 0
B26: TOTAL | C26: =SUM(C16:C25) -> 48 | D26: =SUM(D16:D25) -> 48 | E26: =SUM(E16:E25) -> 48 | F26: =SUM(F16:F25) -> 48 | G26: =SUM(G16:G25) -> 48 | H26: =SUM(H16:H25) -> 48 | I26: =SUM(I16:I25) -> 48 | J26: =SUM(J16:J25) -> 48 | ... M26: =SUM(M16:M25) -> 480
C28: N | D28: S | E28: N | F28: S | G28: N | H28: N | I28: N | J28: S | K28: S | L28: S | O28: MILES | P28: BIL | Q28: GRR | R28: GFV | S28: IDF | T28: MIS | U28: BOI | V28: GJJ | W28: NoCo | X28: OGD | Y28: RMV
B29: TOTAL GAMES | C29: BIL | D29: BOI | E29: GRR | F29: GJJ | G29: GFV | H29: IDF | I29: MIS | J29: NoCo | K29: OGD | L29: RMV | M29: TOTAL | O29: Billings | P29: 0 | Q29: 420 | R29: 218 | S29: 340 | T29: 345 | U29: 599 | V29: 663 | W29: 507 | X29: 516 | Y29: 621
B30: Billings | C30: x | D30: =COUNTIFS(Events!$F$2:$F$481,$B30,Events!$G$2:$G$481,D$29)+COUNTIFS(Events!$H$2:$H$481,D$29,Events!$E$2:$E$481,$B30) -> 6 | E30: =COUNTIFS(Events!$F$2:$F$481,$B30,Events!$G$2:$G$481,E$29)+COUNTIFS(Events!$H$2:$H$481,E$29,Events!$E$2:$E$481,$B30) -> 21 | F30: =COUNTIFS(Events!$F$2:$F$481,$B30,Events!$G$2:$G$481,F$29)+COUNTIFS(Events!$H$2:$H$481,F$29,Events!$E$2:$E$481,$B30) -> 0 | G30: =COUNTIFS(Events!$F$2:$F$481,$B30,Events!$G$2:$G$481,G$29)+COUNTIFS(Events!$H$2:$H$481,G$29,Events!$E$2:$E$481,$B30) -> 21 | H30: =COUNTIFS(Events!$F$2:$F$481,$B30,Events!$G$2:$G$481,H$29)+COUNTIFS(Events!$H$2:$H$481,H$29,Events!$E$2:$E$481,$B30) -> 6 | I30: =COUNTIFS(Events!$F$2:$F$481,$B30,Events!$G$2:$G$481,I$29)+COUNTIFS(Events!$H$2:$H$481,I$29,Events!$E$2:$E$481,$B30) -> 18 | J30: =COUNTIFS(Events!$F$2:$F$481,$B30,Events!$G$2:$G$481,J$29)+COUNTIFS(Events!$H$2:$H$481,J$29,Events!$E$2:$E$481,$B30) -> 15 | K30: =COUNTIFS(Events!$F$2:$F$481,$B30,Events!$G$2:$G$481,K$29)+COUNTIFS(Events!$H$2:$H$481,K$29,Events!$E$2:$E$481,$B30) -> 6 | L30: =COUNTIFS(Events!$F$2:$F$481,$B30,Events!$G$2:$G$481,L$29)+COUNTIFS(Events!$H$2:$H$481,L$29,Events!$E$2:$E$481,$B30) -> 3 | M30: =SUM(C30:L30) -> 96 | O30: Glacier | P30: 420 | Q30: 0 | R30: 225 | S30: 426 | T30: 126 | U30: 482 | V30: 920 | W30: 947 | X30: 604 | Y30: 1061
B31: Boise | C31: =COUNTIFS(Events!$F$2:$F$481,$B31,Events!$G$2:$G$481,C$29)+COUNTIFS(Events!$H$2:$H$481,C$29,Events!$E$2:$E$481,$B31) -> 6 | D31: x | E31: =COUNTIFS(Events!$F$2:$F$481,$B31,Events!$G$2:$G$481,E$29)+COUNTIFS(Events!$H$2:$H$481,E$29,Events!$E$2:$E$481,$B31) -> 9 | F31: =COUNTIFS(Events!$F$2:$F$481,$B31,Events!$G$2:$G$481,F$29)+COUNTIFS(Events!$H$2:$H$481,F$29,Events!$E$2:$E$481,$B31) -> 15 | G31: =COUNTIFS(Events!$F$2:$F$481,$B31,Events!$G$2:$G$481,G$29)+COUNTIFS(Events!$H$2:$H$481,G$29,Events!$E$2:$E$481,$B31) -> 18 | H31: =COUNTIFS(Events!$F$2:$F$481,$B31,Events!$G$2:$G$481,H$29)+COUNTIFS(Events!$H$2:$H$481,H$29,Events!$E$2:$E$481,$B31) -> 12 | I31: =COUNTIFS(Events!$F$2:$F$481,$B31,Events!$G$2:$G$481,I$29)+COUNTIFS(Events!$H$2:$H$481,I$29,Events!$E$2:$E$481,$B31) -> 9 | J31: =COUNTIFS(Events!$F$2:$F$481,$B31,Events!$G$2:$G$481,J$29)+COUNTIFS(Events!$H$2:$H$481,J$29,Events!$E$2:$E$481,$B31) -> 3 | K31: =COUNTIFS(Events!$F$2:$F$481,$B31,Events!$G$2:$G$481,K$29)+COUNTIFS(Events!$H$2:$H$481,K$29,Events!$E$2:$E$481,$B31) -> 18 | L31: =COUNTIFS(Events!$F$2:$F$481,$B31,Events!$G$2:$G$481,L$29)+COUNTIFS(Events!$H$2:$H$481,L$29,Events!$E$2:$E$481,$B31) -> 6 | M31: =SUM(C31:L31) -> 96 | O31: Great Falls | P31: 218 | Q31: 225 | R31: 0 | S31: 362 | T31: 169 | U31: 584 | V31: 855 | W31: 726 | X31: 539 | Y31: 839
B32: Glacier | C32: =COUNTIFS(Events!$F$2:$F$481,$B32,Events!$G$2:$G$481,C$29)+COUNTIFS(Events!$H$2:$H$481,C$29,Events!$E$2:$E$481,$B32) -> 21 | D32: =COUNTIFS(Events!$F$2:$F$481,$B32,Events!$G$2:$G$481,D$29)+COUNTIFS(Events!$H$2:$H$481,D$29,Events!$E$2:$E$481,$B32) -> 9 | E32: x | F32: =COUNTIFS(Events!$F$2:$F$481,$B32,Events!$G$2:$G$481,F$29)+COUNTIFS(Events!$H$2:$H$481,F$29,Events!$E$2:$E$481,$B32) -> 0 | G32: =COUNTIFS(Events!$F$2:$F$481,$B32,Events!$G$2:$G$481,G$29)+COUNTIFS(Events!$H$2:$H$481,G$29,Events!$E$2:$E$481,$B32) -> 18 | H32: =COUNTIFS(Events!$F$2:$F$481,$B32,Events!$G$2:$G$481,H$29)+COUNTIFS(Events!$H$2:$H$481,H$29,Events!$E$2:$E$481,$B32) -> 18 | I32: =COUNTIFS(Events!$F$2:$F$481,$B32,Events!$G$2:$G$481,I$29)+COUNTIFS(Events!$H$2:$H$481,I$29,Events!$E$2:$E$481,$B32) -> 24 | J32: =COUNTIFS(Events!$F$2:$F$481,$B32,Events!$G$2:$G$481,J$29)+COUNTIFS(Events!$H$2:$H$481,J$29,Events!$E$2:$E$481,$B32) -> 0 | K32: =COUNTIFS(Events!$F$2:$F$481,$B32,Events!$G$2:$G$481,K$29)+COUNTIFS(Events!$H$2:$H$481,K$29,Events!$E$2:$E$481,$B32) -> 3 | L32: =COUNTIFS(Events!$F$2:$F$481,$B32,Events!$G$2:$G$481,L$29)+COUNTIFS(Events!$H$2:$H$481,L$29,Events!$E$2:$E$481,$B32) -> 3 | M32: =SUM(C32:L32) -> 96 | O32: Idaho Falls | P32: 338 | Q32: 427 | R32: 362 | S32: 0 | T32: 314 | U32: 264 | V32: 496 | W32: 548 | X32: 180 | Y32: 661
B33: Grand Junction | C33: =COUNTIFS(Events!$F$2:$F$481,$B33,Events!$G$2:$G$481,C$29)+COUNTIFS(Events!$H$2:$H$481,C$29,Events!$E$2:$E$481,$B33) -> 0 | D33: =COUNTIFS(Events!$F$2:$F$481,$B33,Events!$G$2:$G$481,D$29)+COUNTIFS(Events!$H$2:$H$481,D$29,Events!$E$2:$E$481,$B33) -> 15 | E33: =COUNTIFS(Events!$F$2:$F$481,$B33,Events!$G$2:$G$481,E$29)+COUNTIFS(Events!$H$2:$H$481,E$29,Events!$E$2:$E$481,$B33) -> 0 | F33: x | G33: =COUNTIFS(Events!$F$2:$F$481,$B33,Events!$G$2:$G$481,G$29)+COUNTIFS(Events!$H$2:$H$481,G$29,Events!$E$2:$E$481,$B33) -> 0 | H33: =COUNTIFS(Events!$F$2:$F$481,$B33,Events!$G$2:$G$481,H$29)+COUNTIFS(Events!$H$2:$H$481,H$29,Events!$E$2:$E$481,$B33) -> 15 | I33: =COUNTIFS(Events!$F$2:$F$481,$B33,Events!$G$2:$G$481,I$29)+COUNTIFS(Events!$H$2:$H$481,I$29,Events!$E$2:$E$481,$B33) -> 0 | J33: =COUNTIFS(Events!$F$2:$F$481,$B33,Events!$G$2:$G$481,J$29)+COUNTIFS(Events!$H$2:$H$481,J$29,Events!$E$2:$E$481,$B33) -> 30 | K33: =COUNTIFS(Events!$F$2:$F$481,$B33,Events!$G$2:$G$481,K$29)+COUNTIFS(Events!$H$2:$H$481,K$29,Events!$E$2:$E$481,$B33) -> 9 | L33: =COUNTIFS(Events!$F$2:$F$481,$B33,Events!$G$2:$G$481,L$29)+COUNTIFS(Events!$H$2:$H$481,L$29,Events!$E$2:$E$481,$B33) -> 27 | M33: =SUM(C33:L33) -> 96 | O33: Missoula | P33: 345 | Q33: 125 | R33: 169 | S33: 313 | T33: 0 | U33: 359 | V33: 806 | W33: 851 | X33: 490 | Y33: 965
B34: Great Falls | C34: =COUNTIFS(Events!$F$2:$F$481,$B34,Events!$G$2:$G$481,C$29)+COUNTIFS(Events!$H$2:$H$481,C$29,Events!$E$2:$E$481,$B34) -> 21 | D34: =COUNTIFS(Events!$F$2:$F$481,$B34,Events!$G$2:$G$481,D$29)+COUNTIFS(Events!$H$2:$H$481,D$29,Events!$E$2:$E$481,$B34) -> 18 | E34: =COUNTIFS(Events!$F$2:$F$481,$B34,Events!$G$2:$G$481,E$29)+COUNTIFS(Events!$H$2:$H$481,E$29,Events!$E$2:$E$481,$B34) -> 18 | F34: =COUNTIFS(Events!$F$2:$F$481,$B34,Events!$G$2:$G$481,F$29)+COUNTIFS(Events!$H$2:$H$481,F$29,Events!$E$2:$E$481,$B34) -> 0 | G34: x | H34: =COUNTIFS(Events!$F$2:$F$481,$B34,Events!$G$2:$G$481,H$29)+COUNTIFS(Events!$H$2:$H$481,H$29,Events!$E$2:$E$481,$B34) -> 9 | I34: =COUNTIFS(Events!$F$2:$F$481,$B34,Events!$G$2:$G$481,I$29)+COUNTIFS(Events!$H$2:$H$481,I$29,Events!$E$2:$E$481,$B34) -> 24 | J34: =COUNTIFS(Events!$F$2:$F$481,$B34,Events!$G$2:$G$481,J$29)+COUNTIFS(Events!$H$2:$H$481,J$29,Events!$E$2:$E$481,$B34) -> 6 | K34: =COUNTIFS(Events!$F$2:$F$481,$B34,Events!$G$2:$G$481,K$29)+COUNTIFS(Events!$H$2:$H$481,K$29,Events!$E$2:$E$481,$B34) -> 0 | L34: =COUNTIFS(Events!$F$2:$F$481,$B34,Events!$G$2:$G$481,L$29)+COUNTIFS(Events!$H$2:$H$481,L$29,Events!$E$2:$E$481,$B34) -> 0 | M34: =SUM(C34:L34) -> 96 | O34: Boise | P34: 620 | Q34: 482 | R34: 584 | S34: 264 | T34: 359 | U34: 0 | V34: 628 | W34: 775 | X34: 311 | Y34: 889
B35: Idaho Falls | C35: =COUNTIFS(Events!$F$2:$F$481,$B35,Events!$G$2:$G$481,C$29)+COUNTIFS(Events!$H$2:$H$481,C$29,Events!$E$2:$E$481,$B35) -> 6 | D35: =COUNTIFS(Events!$F$2:$F$481,$B35,Events!$G$2:$G$481,D$29)+COUNTIFS(Events!$H$2:$H$481,D$29,Events!$E$2:$E$481,$B35) -> 12 | E35: =COUNTIFS(Events!$F$2:$F$481,$B35,Events!$G$2:$G$481,E$29)+COUNTIFS(Events!$H$2:$H$481,E$29,Events!$E$2:$E$481,$B35) -> 18 | F35: =COUNTIFS(Events!$F$2:$F$481,$B35,Events!$G$2:$G$481,F$29)+COUNTIFS(Events!$H$2:$H$481,F$29,Events!$E$2:$E$481,$B35) -> 15 | G35: =COUNTIFS(Events!$F$2:$F$481,$B35,Events!$G$2:$G$481,G$29)+COUNTIFS(Events!$H$2:$H$481,G$29,Events!$E$2:$E$481,$B35) -> 9 | H35: x | I35: =COUNTIFS(Events!$F$2:$F$481,$B35,Events!$G$2:$G$481,I$29)+COUNTIFS(Events!$H$2:$H$481,I$29,Events!$E$2:$E$481,$B35) -> 9 | J35: =COUNTIFS(Events!$F$2:$F$481,$B35,Events!$G$2:$G$481,J$29)+COUNTIFS(Events!$H$2:$H$481,J$29,Events!$E$2:$E$481,$B35) -> 6 | K35: =COUNTIFS(Events!$F$2:$F$481,$B35,Events!$G$2:$G$481,K$29)+COUNTIFS(Events!$H$2:$H$481,K$29,Events!$E$2:$E$481,$B35) -> 18 | L35: =COUNTIFS(Events!$F$2:$F$481,$B35,Events!$G$2:$G$481,L$29)+COUNTIFS(Events!$H$2:$H$481,L$29,Events!$E$2:$E$481,$B35) -> 3 | M35: =SUM(C35:L35) -> 96 | O35: Grand Junction | P35: 663 | Q35: 920 | R35: 855 | S35: 496 | T35: 806 | U35: 627 | V35: 0 | W35: 298 | X35: 319 | Y35: 311
B36: Missoula | C36: =COUNTIFS(Events!$F$2:$F$481,$B36,Events!$G$2:$G$481,C$29)+COUNTIFS(Events!$H$2:$H$481,C$29,Events!$E$2:$E$481,$B36) -> 18 | D36: =COUNTIFS(Events!$F$2:$F$481,$B36,Events!$G$2:$G$481,D$29)+COUNTIFS(Events!$H$2:$H$481,D$29,Events!$E$2:$E$481,$B36) -> 9 | E36: =COUNTIFS(Events!$F$2:$F$481,$B36,Events!$G$2:$G$481,E$29)+COUNTIFS(Events!$H$2:$H$481,E$29,Events!$E$2:$E$481,$B36) -> 24 | F36: =COUNTIFS(Events!$F$2:$F$481,$B36,Events!$G$2:$G$481,F$29)+COUNTIFS(Events!$H$2:$H$481,F$29,Events!$E$2:$E$481,$B36) -> 0 | G36: =COUNTIFS(Events!$F$2:$F$481,$B36,Events!$G$2:$G$481,G$29)+COUNTIFS(Events!$H$2:$H$481,G$29,Events!$E$2:$E$481,$B36) -> 24 | H36: =COUNTIFS(Events!$F$2:$F$481,$B36,Events!$G$2:$G$481,H$29)+COUNTIFS(Events!$H$2:$H$481,H$29,Events!$E$2:$E$481,$B36) -> 9 | I36: x | J36: =COUNTIFS(Events!$F$2:$F$481,$B36,Events!$G$2:$G$481,J$29)+COUNTIFS(Events!$H$2:$H$481,J$29,Events!$E$2:$E$481,$B36) -> 0 | K36: =COUNTIFS(Events!$F$2:$F$481,$B36,Events!$G$2:$G$481,K$29)+COUNTIFS(Events!$H$2:$H$481,K$29,Events!$E$2:$E$481,$B36) -> 9 | L36: =COUNTIFS(Events!$F$2:$F$481,$B36,Events!$G$2:$G$481,L$29)+COUNTIFS(Events!$H$2:$H$481,L$29,Events!$E$2:$E$481,$B36) -> 3 | M36: =SUM(C36:L36) -> 96 | O36: NoCo | P36: 507 | Q36: 947 | R36: 726 | S36: 546 | T36: 851 | U36: 775 | V36: 298 | W36: 0 | X36: 467 | Y36: 126
B37: NoCo | C37: =COUNTIFS(Events!$F$2:$F$481,$B37,Events!$G$2:$G$481,C$29)+COUNTIFS(Events!$H$2:$H$481,C$29,Events!$E$2:$E$481,$B37) -> 15 | D37: =COUNTIFS(Events!$F$2:$F$481,$B37,Events!$G$2:$G$481,D$29)+COUNTIFS(Events!$H$2:$H$481,D$29,Events!$E$2:$E$481,$B37) -> 3 | E37: =COUNTIFS(Events!$F$2:$F$481,$B37,Events!$G$2:$G$481,E$29)+COUNTIFS(Events!$H$2:$H$481,E$29,Events!$E$2:$E$481,$B37) -> 0 | F37: =COUNTIFS(Events!$F$2:$F$481,$B37,Events!$G$2:$G$481,F$29)+COUNTIFS(Events!$H$2:$H$481,F$29,Events!$E$2:$E$481,$B37) -> 30 | G37: =COUNTIFS(Events!$F$2:$F$481,$B37,Events!$G$2:$G$481,G$29)+COUNTIFS(Events!$H$2:$H$481,G$29,Events!$E$2:$E$481,$B37) -> 6 | H37: =COUNTIFS(Events!$F$2:$F$481,$B37,Events!$G$2:$G$481,H$29)+COUNTIFS(Events!$H$2:$H$481,H$29,Events!$E$2:$E$481,$B37) -> 6 | I37: =COUNTIFS(Events!$F$2:$F$481,$B37,Events!$G$2:$G$481,I$29)+COUNTIFS(Events!$H$2:$H$481,I$29,Events!$E$2:$E$481,$B37) -> 0 | J37: x | K37: =COUNTIFS(Events!$F$2:$F$481,$B37,Events!$G$2:$G$481,K$29)+COUNTIFS(Events!$H$2:$H$481,K$29,Events!$E$2:$E$481,$B37) -> 9 | L37: =COUNTIFS(Events!$F$2:$F$481,$B37,Events!$G$2:$G$481,L$29)+COUNTIFS(Events!$H$2:$H$481,L$29,Events!$E$2:$E$481,$B37) -> 27 | M37: =SUM(C37:L37) -> 96 | O37: Ogden | P37: 516 | Q37: 604 | R37: 539 | S37: 180 | T37: 491 | U37: 311 | V37: 319 | W37: 469 | X37: 0 | Y37: 583
B38: Ogden | C38: =COUNTIFS(Events!$F$2:$F$481,$B38,Events!$G$2:$G$481,C$29)+COUNTIFS(Events!$H$2:$H$481,C$29,Events!$E$2:$E$481,$B38) -> 6 | D38: =COUNTIFS(Events!$F$2:$F$481,$B38,Events!$G$2:$G$481,D$29)+COUNTIFS(Events!$H$2:$H$481,D$29,Events!$E$2:$E$481,$B38) -> 18 | E38: =COUNTIFS(Events!$F$2:$F$481,$B38,Events!$G$2:$G$481,E$29)+COUNTIFS(Events!$H$2:$H$481,E$29,Events!$E$2:$E$481,$B38) -> 3 | F38: =COUNTIFS(Events!$F$2:$F$481,$B38,Events!$G$2:$G$481,F$29)+COUNTIFS(Events!$H$2:$H$481,F$29,Events!$E$2:$E$481,$B38) -> 9 | G38: =COUNTIFS(Events!$F$2:$F$481,$B38,Events!$G$2:$G$481,G$29)+COUNTIFS(Events!$H$2:$H$481,G$29,Events!$E$2:$E$481,$B38) -> 0 | H38: =COUNTIFS(Events!$F$2:$F$481,$B38,Events!$G$2:$G$481,H$29)+COUNTIFS(Events!$H$2:$H$481,H$29,Events!$E$2:$E$481,$B38) -> 18 | I38: =COUNTIFS(Events!$F$2:$F$481,$B38,Events!$G$2:$G$481,I$29)+COUNTIFS(Events!$H$2:$H$481,I$29,Events!$E$2:$E$481,$B38) -> 9 | J38: =COUNTIFS(Events!$F$2:$F$481,$B38,Events!$G$2:$G$481,J$29)+COUNTIFS(Events!$H$2:$H$481,J$29,Events!$E$2:$E$481,$B38) -> 9 | K38: x | L38: =COUNTIFS(Events!$F$2:$F$481,$B38,Events!$G$2:$G$481,L$29)+COUNTIFS(Events!$H$2:$H$481,L$29,Events!$E$2:$E$481,$B38) -> 24 | M38: =SUM(C38:L38) -> 96 | O38: Rocky Mountain | P38: 621 | Q38: 1061 | R38: 839 | S38: 659 | T38: 965 | U38: 889 | V38: 311 | W38: 126 | X38: 580 | Y38: 0
B39: Rocky Mountain | C39: =COUNTIFS(Events!$F$2:$F$481,$B39,Events!$G$2:$G$481,C$29)+COUNTIFS(Events!$H$2:$H$481,C$29,Events!$E$2:$E$481,$B39) -> 3 | D39: =COUNTIFS(Events!$F$2:$F$481,$B39,Events!$G$2:$G$481,D$29)+COUNTIFS(Events!$H$2:$H$481,D$29,Events!$E$2:$E$481,$B39) -> 6 | E39: =COUNTIFS(Events!$F$2:$F$481,$B39,Events!$G$2:$G$481,E$29)+COUNTIFS(Events!$H$2:$H$481,E$29,Events!$E$2:$E$481,$B39) -> 3 | F39: =COUNTIFS(Events!$F$2:$F$481,$B39,Events!$G$2:$G$481,F$29)+COUNTIFS(Events!$H$2:$H$481,F$29,Events!$E$2:$E$481,$B39) -> 27 | G39: =COUNTIFS(Events!$F$2:$F$481,$B39,Events!$G$2:$G$481,G$29)+COUNTIFS(Events!$H$2:$H$481,G$29,Events!$E$2:$E$481,$B39) -> 0 | H39: =COUNTIFS(Events!$F$2:$F$481,$B39,Events!$G$2:$G$481,H$29)+COUNTIFS(Events!$H$2:$H$481,H$29,Events!$E$2:$E$481,$B39) -> 3 | I39: =COUNTIFS(Events!$F$2:$F$481,$B39,Events!$G$2:$G$481,I$29)+COUNTIFS(Events!$H$2:$H$481,I$29,Events!$E$2:$E$481,$B39) -> 3 | J39: =COUNTIFS(Events!$F$2:$F$481,$B39,Events!$G$2:$G$481,J$29)+COUNTIFS(Events!$H$2:$H$481,J$29,Events!$E$2:$E$481,$B39) -> 27 | K39: =COUNTIFS(Events!$F$2:$F$481,$B39,Events!$G$2:$G$481,K$29)+COUNTIFS(Events!$H$2:$H$481,K$29,Events!$E$2:$E$481,$B39) -> 24 | L39: x | M39: =SUM(C39:L39) -> 96
B40: TOTAL | C40: =SUM(C30:C39) -> 96 | D40: =SUM(D30:D39) -> 96 | E40: =SUM(E30:E39) -> 96 | F40: =SUM(F30:F39) -> 96 | G40: =SUM(G30:G39) -> 96 | H40: =SUM(H30:H39) -> 96 | I40: =SUM(I30:I39) -> 96 | J40: =SUM(J30:J39) -> 96 | ... M40: =SUM(M30:M39) -> 960
P42: N | Q42: N | R42: N | S42: N | T42: N | U42: S | V42: S | W42: S | X42: S | Y42: S
B43: TOTAL GAMES | C43: N | D43: S | E43: TOTAL | F43: %N | G43: %S | O43: TOTAL GAMES | P43: BIL | Q43: GRR | R43: GFV | S43: IDF | T43: MIS | U43: BOI | V43: GJJ | W43: NoCo | X43: OGD | Y43: RMV | Z43: TOTAL
B44: Billings | C44: =SUMIF($C$28:$L$28,$C$43,C30:L30) -> 66 | D44: =SUMIF($C$28:$L$28,$D$43,C30:L30) -> 30 | E44: =SUM(C44:D44) -> 96 | F44: =C44/$E$44 -> 0.6875 | G44: =D44/$E$44 -> 0.3125 | O44: Billings | P44: x | Q44: 21 | R44: 21 | S44: 6 | T44: 18 | U44: 6 | V44: 0 | W44: 15 | X44: 6 | Y44: 3 | Z44: 96
B45: Glacier | C45: =SUMIF($C$28:$L$28,$C$43,C32:L32) -> 81 | D45: =SUMIF($C$28:$L$28,$D$43,C32:L32) -> 15 | E45: =SUM(C45:D45) -> 96 | F45: =C45/$E$44 -> 0.84375 | G45: =D45/$E$44 -> 0.15625 | O45: Glacier | P45: 21 | Q45: x | R45: 18 | S45: 18 | T45: 24 | U45: 9 | V45: 0 | W45: 0 | X45: 3 | Y45: 3 | Z45: 96
...

Sheet Events
A1: Event ID | B1: Game Date | C1: Away Team | D1: Home Team | E1: Away_City | F1: Home_City | G1: Away_Code | H1: Home_Code | J1: Billings Mustangs | K1: Billings | L1: BIL
A2: 2f3xe1uoikt3o95x | B2: 45069.729 | C2: Grand Junction Jackalopes | D2: Ogden Raptors | E2: =VLOOKUP(C2,$J$1:$L$10,2,FALSE) -> Grand Junction | F2: =VLOOKUP(D2,$J$1:$L$10,2,FALSE) -> Ogden | G2: =VLOOKUP(C2,$J$1:$L$10,3,FALSE) -> GJJ | H2: =VLOOKUP(D2,$J$1:$L$10,3,FALSE) -> OGD | J2: Boise Hawks | K2: Boise | L2: BOI
A3: qeff2gr8qz16awz3 | B3: 45069.733 | C3: Missoula PaddleHeads | D3: Billings Mustangs | E3: =VLOOKUP(C3,$J$1:$L$10,2,FALSE) -> Missoula | F3: =VLOOKUP(D3,$J$1:$L$10,2,FALSE) -> Billings | G3: =VLOOKUP(C3,$J$1:$L$10,3,FALSE) -> MIS | H3: =VLOOKUP(D3,$J$1:$L$10,3,FALSE) -> BIL | J3: Glacier Range Riders | K3: Glacier | L3: GRR
A4: uhmkve4nngsjf67d | B4: 45069.75 | C4: Glacier Range Riders | D4: Great Falls Voyagers | E4: =VLOOKUP(C4,$J$1:$L$10,2,FALSE) -> Glacier | F4: =VLOOKUP(D4,$J$1:$L$10,2,FALSE) -> Great Falls | G4: =VLOOKUP(C4,$J$1:$L$10,3,FALSE) -> GRR | H4: =VLOOKUP(D4,$J$1:$L$10,3,FALSE) -> GFV | J4: Grand Junction Jackalopes | K4: Grand Junction | L4: GJJ
A5: uutvtu1p08bnulrf | B5: 45069.753 | C5: Idaho Falls Chukars | D5: Boise Hawks | E5: =VLOOKUP(C5,$J$1:$L$10,2,FALSE) -> Idaho Falls | F5: =VLOOKUP(D5,$J$1:$L$10,2,FALSE) -> Boise | G5: =VLOOKUP(C5,$J$1:$L$10,3,FALSE) -> IDF | H5: =VLOOKUP(D5,$J$1:$L$10,3,FALSE) -> BOI | J5: Great Falls Voyagers | K5: Great Falls | L5: GFV
A6: ga23xog5qtk5g0qy | B6: 45069.753 | C6: Rocky Mountain Vibes | D6: Northern Colorado Owlz | E6: =VLOOKUP(C6,$J$1:$L$10,2,FALSE) -> Rocky Mountain | F6: =VLOOKUP(D6,$J$1:$L$10,2,FALSE) -> NoCo | G6: =VLOOKUP(C6,$J$1:$L$10,3,FALSE) -> RMV | H6: =VLOOKUP(D6,$J$1:$L$10,3,FALSE) -> NoCo | J6: Idaho Falls Chukars | K6: Idaho Falls | L6: IDF
A7: cvu4p0zwggth2uhq | B7: 45070.729 | C7: Grand Junction Jackalopes | D7: Ogden Raptors | E7: =VLOOKUP(C7,$J$1:$L$10,2,FALSE) -> Grand Junction | F7: =VLOOKUP(D7,$J$1:$L$10,2,FALSE) -> Ogden | G7: =VLOOKUP(C7,$J$1:$L$10,3,FALSE) -> GJJ | H7: =VLOOKUP(D7,$J$1:$L$10,3,FALSE) -> OGD | J7: Missoula PaddleHeads | K7: Missoula | L7: MIS
A8: osdgurscksjtddc6 | B8: 45070.733 | C8: Missoula PaddleHeads | D8: Billings Mustangs | E8: =VLOOKUP(C8,$J$1:$L$10,2,FALSE) -> Missoula | F8: =VLOOKUP(D8,$J$1:$L$10,2,FALSE) -> Billings | G8: =VLOOKUP(C8,$J$1:$L$10,3,FALSE) -> MIS | H8: =VLOOKUP(D8,$J$1:$L$10,3,FALSE) -> BIL | J8: Northern Colorado Owlz | K8: NoCo | L8: NoCo
A9: 61ly7nt67zqpw11t | B9: 45070.75 | C9: Glacier Range Riders | D9: Great Falls Voyagers | E9: =VLOOKUP(C9,$J$1:$L$10,2,FALSE) -> Glacier | F9: =VLOOKUP(D9,$J$1:$L$10,2,FALSE) -> Great Falls | G9: =VLOOKUP(C9,$J$1:$L$10,3,FALSE) -> GRR | H9: =VLOOKUP(D9,$J$1:$L$10,3,FALSE) -> GFV | J9: Ogden Raptors | K9: Ogden | L9: OGD
A10: mmkiwa5l85j7zkic | B10: 45070.753 | C10: Idaho Falls Chukars | D10: Boise Hawks | E10: =VLOOKUP(C10,$J$1:$L$10,2,FALSE) -> Idaho Falls | F10: =VLOOKUP(D10,$J$1:$L$10,2,FALSE) -> Boise | G10: =VLOOKUP(C10,$J$1:$L$10,3,FALSE) -> IDF | H10: =VLOOKUP(D10,$J$1:$L$10,3,FALSE) -> BOI | J10: Rocky Mountain Vibes | K10: Rocky Mountain | L10: RMV
A11: 9zrk3lmmy8lg5pep | B11: 45070.753 | C11: Rocky Mountain Vibes | D11: Northern Colorado Owlz | E11: =VLOOKUP(C11,$J$1:$L$10,2,FALSE) -> Rocky Mountain | F11: =VLOOKUP(D11,$J$1:$L$10,2,FALSE) -> NoCo | G11: =VLOOKUP(C11,$J$1:$L$10,3,FALSE) -> RMV | H11: =VLOOKUP(D11,$J$1:$L$10,3,FALSE) -> NoCo
A12: 3xmk38am6owe6uma | B12: 45071.729 | C12: Grand Junction Jackalopes | D12: Ogden Raptors | E12: =VLOOKUP(C12,$J$1:$L$10,2,FALSE) -> Grand Junction | F12: =VLOOKUP(D12,$J$1:$L$10,2,FALSE) -> Ogden | G12: =VLOOKUP(C12,$J$1:$L$10,3,FALSE) -> GJJ | H12: =VLOOKUP(D12,$J$1:$L$10,3,FALSE) -> OGD
A13: bpvdq03gyi1b7am9 | B13: 45071.733 | C13: Missoula PaddleHeads | D13: Billings Mustangs | E13: =VLOOKUP(C13,$J$1:$L$10,2,FALSE) -> Missoula | F13: =VLOOKUP(D13,$J$1:$L$10,2,FALSE) -> Billings | G13: =VLOOKUP(C13,$J$1:$L$10,3,FALSE) -> MIS | H13: =VLOOKUP(D13,$J$1:$L$10,3,FALSE) -> BIL
A14: 7mtm7px1kcznnhkj | B14: 45071.75 | C14: Glacier Range Riders | D14: Great Falls Voyagers | E14: =VLOOKUP(C14,$J$1:$L$10,2,FALSE) -> Glacier | F14: =VLOOKUP(D14,$J$1:$L$10,2,FALSE) -> Great Falls | G14: =VLOOKUP(C14,$J$1:$L$10,3,FALSE) -> GRR | H14: =VLOOKUP(D14,$J$1:$L$10,3,FALSE) -> GFV
A15: qbbwntmbeldoptli | B15: 45071.753 | C15: Idaho Falls Chukars | D15: Boise Hawks | E15: =VLOOKUP(C15,$J$1:$L$10,2,FALSE) -> Idaho Falls | F15: =VLOOKUP(D15,$J$1:$L$10,2,FALSE) -> Boise | G15: =VLOOKUP(C15,$J$1:$L$10,3,FALSE) -> IDF | H15: =VLOOKUP(D15,$J$1:$L$10,3,FALSE) -> BOI
A16: hed30kf7rsy7jbks | B16: 45071.753 | C16: Rocky Mountain Vibes | D16: Northern Colorado Owlz | E16: =VLOOKUP(C16,$J$1:$L$10,2,FALSE) -> Rocky Mountain | F16: =VLOOKUP(D16,$J$1:$L$10,2,FALSE) -> NoCo | G16: =VLOOKUP(C16,$J$1:$L$10,3,FALSE) -> RMV | H16: =VLOOKUP(D16,$J$1:$L$10,3,FALSE) -> NoCo
A17: wprtkijvdxogcct9 | B17: 45072.729 | C17: Grand Junction Jackalopes | D17: Ogden Raptors | E17: =VLOOKUP(C17,$J$1:$L$10,2,FALSE) -> Grand Junction | F17: =VLOOKUP(D17,$J$1:$L$10,2,FALSE) -> Ogden | G17: =VLOOKUP(C17,$J$1:$L$10,3,FALSE) -> GJJ | H17: =VLOOKUP(D17,$J$1:$L$10,3,FALSE) -> OGD
A18: wbn30y5tou8irfxj | B18: 45072.733 | C18: Missoula PaddleHeads | D18: Billings Mustangs | E18: =VLOOKUP(C18,$J$1:$L$10,2,FALSE) -> Missoula | F18: =VLOOKUP(D18,$J$1:$L$10,2,FALSE) -> Billings | G18: =VLOOKUP(C18,$J$1:$L$10,3,FALSE) -> MIS | H18: =VLOOKUP(D18,$J$1:$L$10,3,FALSE) -> BIL
A19: ddjeh10wolossx11 | B19: 45072.75 | C19: Glacier Range Riders | D19: Great Falls Voyagers | E19: =VLOOKUP(C19,$J$1:$L$10,2,FALSE) -> Glacier | F19: =VLOOKUP(D19,$J$1:$L$10,2,FALSE) -> Great Falls | G19: =VLOOKUP(C19,$J$1:$L$10,3,FALSE) -> GRR | H19: =VLOOKUP(D19,$J$1:$L$10,3,FALSE) -> GFV
A20: 7c5dettt0mcrny0q | B20: 45072.753 | C20: Boise Hawks | D20: Idaho Falls Chukars | E20: =VLOOKUP(C20,$J$1:$L$10,2,FALSE) -> Boise | F20: =VLOOKUP(D20,$J$1:$L$10,2,FALSE) -> Idaho Falls | G20: =VLOOKUP(C20,$J$1:$L$10,3,FALSE) -> BOI | H20: =VLOOKUP(D20,$J$1:$L$10,3,FALSE) -> IDF
A21: 9ulevkngopnpv1sm | B21: 45072.753 | C21: Rocky Mountain Vibes | D21: Northern Colorado Owlz | E21: =VLOOKUP(C21,$J$1:$L$10,2,FALSE) -> Rocky Mountain | F21: =VLOOKUP(D21,$J$1:$L$10,2,FALSE) -> NoCo | G21: =VLOOKUP(C21,$J$1:$L$10,3,FALSE) -> RMV | H21: =VLOOKUP(D21,$J$1:$L$10,3,FALSE) -> NoCo
A22: zgi7jes9c8kdwpub | B22: 45073.729 | C22: Grand Junction Jackalopes | D22: Ogden Raptors | E22: =VLOOKUP(C22,$J$1:$L$10,2,FALSE) -> Grand Junction | F22: =VLOOKUP(D22,$J$1:$L$10,2,FALSE) -> Ogden | G22: =VLOOKUP(C22,$J$1:$L$10,3,FALSE) -> GJJ | H22: =VLOOKUP(D22,$J$1:$L$10,3,FALSE) -> OGD
... A481: w17azwgs5k5136xv | B481: 45178.753 | C481: Ogden Raptors | D481: Idaho Falls Chukars | E481: =VLOOKUP(C481,$J$1:$L$10,2,FALSE) -> Ogden | F481: =VLOOKUP(D481,$J$1:$L$10,2,FALSE) -> Idaho Falls | G481: =VLOOKUP(C481,$J$1:$L$10,3,FALSE) -> OGD | H481: =VLOOKUP(D481,$J$1:$L$10,3,FALSE) -> IDF

Sheet Date Preferences
B2: SCHEDULE | C2: Preference (Wants to be Home) | D2: Blackouts (Wants to be Away) | G2: Key Dates Summary
B3: Billings | C3: - | D3: May 23-27, Jun 26-Jul 1, Aug 6-12, Sep 4-8 | G3: May | H3: Home | I3: Away | J3: August | K3: Home | L3: Away
B4: Boise | C4: Jun 16, Jul 4 | D4: Jun 22, Jul 16-20, Aug 16-25 | G4: 21 | I4: NoCo, RMV | J4: 5
B5: Glacier | C5: - | D5: Aug 14-18 | G5: 22 | I5: NoCo, RMV | J5: 6 | L5: BIL
B6: Grand Junction | C6: 45111 | D6: Not before Jun 4 nor FRI/SAT/SUN after Aug 22 | G6: 23 | I6: BIL, NoCo, RMV | J6: 7 | L6: BIL
B7: Great Falls | C7: 45111 | D7: - | G7: 24 | I7: BIL, NoCo, RMV | J7: 8 | L7: BIL, MIS
B8: Idaho Falls | C8: 45111 | D8: - | G8: 25 | I8: BIL, NoCo, RMV, MIS | J8: 9 | L8: BIL, MIS
B9: Missoula | C9: Jun 14-16, Jun 28-29, Aug 27-29 | D9: May 25-27, Jun 1, Aug 8-11, Aug 23-25, Aug 31 | G9: 26 | I9: BIL, NoCo, RMV, MIS | J9: 10 | L9: BIL, MIS
B10: NoCo | C10: Jun 16, Jul 4, Sep 2 | D10: May 21-26 | G10: 27 | I10: BIL, MIS | J10: 11 | L10: BIL, MIS
B11: Ogden | C11: - | D11: Jun 8, Jul 4, Jul 24 | G11: June | H11: Home | I11: Away | J11: 12 | L11: BIL
B12: Rocky Mountain | C12: Jul 4, More games in Jun/Aug, End Season at Home | D12: May 21-26, Avoid Home in July (Rains) | G12: 1 | I12: MIS | J12: 14 | L12: GRR
G13: 3 | I13: GJJ (Incl. every date prior to this) | J13: 15 | L13: GRR
G14: 4 | H14: (First potential GJJ Home Date) | J14: 16 | L14: BOI, GRR
G15: 8 | I15: OGD | J15: 17 | L15: BOI, GRR
G16: 10 | J16: 18 | L16: BOI, GRR
G17: 14 | H17: MIS | J17: 19 | L17: BOI
G18: 15 | H18: MIS | J18: 20 | L18: BOI
G19: 16 | H19: BOI, NoCo, MIS | J19: 21 | L19: BOI
G20: 17 | J20: 22 | L20: BOI, (GJJ Away on FRI/SAT/SUN after this date)
G21: 22 | I21: BOI | J21: 23 | L21: BOI, MIS
G22: 24 | J22: 24 | L22: BOI, MIS
G23: 26 | I23: BIL | J23: 25 | L23: BOI, MIS
G24: 27 | I24: BIL | J24: 26
G25: 28 | H25: MIS | I25: BIL | J25: 27 | K25: MIS
G26: 29 | H26: MIS | I26: BIL | J26: 28 | K26: MIS
G27: 30 | I27: BIL | J27: 29 | K27: MIS
G28: July | H28: Home | I28: Away | J28: 31 | L28: MIS
G29: 1 | I29: BIL | J29: September | K29: Home | L29: Away
G30: 4 | H30: BOI, GJJ, GFV, IDF, NoCo, RMV | I30: MIS, OGD | J30: 2 | K30: NoCo
G31: 8 | J31: 4 | L31: BIL
G32: 15 | J32: 5 | L32: BIL
G33: 16 | I33: BOI | J33: 6 | L33: BIL
G34: 17 | I34: BOI | J34: 7 | L34: BIL
G35: 18 | I35: BOI | J35: 8 | L35: BIL
G36: 19 | I36: BOI
G37: 20 | I37: BOI
G38: 22
G39: 24 | I39: OGD
G40: 29
